<?xml version="1.0" ?>
<!-- =================================================================================== -->
<!-- |    This document was autogenerated by xacro from rx170.xacro                    | -->
<!-- |    EDITING THIS FILE BY HAND IS NOT RECOMMENDED                                 | -->
<!-- =================================================================================== -->
<robot name="staubli_rx170" xmlns:xacro="http://ros.org/wiki/xacro">
  <link name="base_link">
    <visual>
      <geometry>
        <mesh filename="package://staubli_rx170_support/meshes/visual/base_link.dae"/>
      </geometry>
    </visual>
    <collision>
      <geometry>
        <mesh filename="package://staubli_rx170_support/meshes/collision/base_link.dae"/>
      </geometry>
    </collision>
  </link>
  <joint name="joint_1" type="revolute">
    <parent link="base_link"/>
    <child link="shoulder_link"/>
    <origin xyz="0 0 0.75"/>
    <axis xyz="0 0 1"/>
    <limit effort="1000" lower="-3.142" upper="3.142" velocity="2.705"/>
  </joint>
  <link name="shoulder_link">
    <visual>
      <geometry>
        <mesh filename="package://staubli_rx170_support/meshes/visual/shoulder_link.dae"/>
      </geometry>
    </visual>
    <collision>
      <geometry>
        <mesh filename="package://staubli_rx170_support/meshes/collision/shoulder_link.dae"/>
      </geometry>
    </collision>
  </link>
  <joint name="joint_2" type="revolute">
    <parent link="shoulder_link"/>
    <child link="arm_link"/>
    <origin xyz="0.1 0 0"/>
    <axis xyz="0 1 0"/>
    <limit effort="1000" lower="-2.094" upper="2.094" velocity="2.269"/>
  </joint>
  <link name="arm_link">
    <visual>
      <geometry>
        <mesh filename="package://staubli_rx170_support/meshes/visual/arm_link.dae"/>
      </geometry>
    </visual>
    <collision>
      <geometry>
        <mesh filename="package://staubli_rx170_support/meshes/collision/arm_link.dae"/>
      </geometry>
    </collision>
  </link>
  <joint name="joint_3" type="revolute">
    <parent link="arm_link"/>
    <child link="elbow_link"/>
    <origin xyz="0 0.07 0.85"/>
    <axis xyz="0 -1 0"/>
    <limit effort="1000" lower="-2.269" upper="2.269" velocity="3.578"/>
  </joint>
  <link name="elbow_link">
    <visual>
      <geometry>
        <mesh filename="package://staubli_rx170_support/meshes/visual/elbow_link.dae"/>
      </geometry>
    </visual>
    <collision>
      <geometry>
        <mesh filename="package://staubli_rx170_support/meshes/collision/elbow_link.dae"/>
      </geometry>
    </collision>
  </link>
  <joint name="joint_4" type="revolute">
    <parent link="elbow_link"/>
    <child link="forearm_link"/>
    <origin xyz="0 0 0"/>
    <axis xyz="0 0 1"/>
    <limit effort="1000" lower="-3.142" upper="3.142" velocity="4.136"/>
  </joint>
  <link name="forearm_link">
    <visual>
      <geometry>
        <mesh filename="package://staubli_rx170_support/meshes/visual/forearm_link.dae"/>
      </geometry>
    </visual>
    <collision>
      <geometry>
        <mesh filename="package://staubli_rx170_support/meshes/collision/forearm_link.dae"/>
      </geometry>
    </collision>
  </link>
  <joint name="joint_5" type="revolute">
    <parent link="forearm_link"/>
    <child link="wrist_link"/>
    <origin xyz="0 0 0.77"/>
    <axis xyz="0 1 0"/>
    <limit effort="1000" lower="-2.094" upper="2.094" velocity="2.635"/>
  </joint>
  <link name="wrist_link">
    <visual>
      <geometry>
        <mesh filename="package://staubli_rx170_support/meshes/visual/wrist_link.dae"/>
      </geometry>
    </visual>
    <collision>
      <geometry>
        <mesh filename="package://staubli_rx170_support/meshes/collision/wrist_link.dae"/>
      </geometry>
    </collision>
  </link>
  <joint name="joint_6" type="continuous">
    <parent link="wrist_link"/>
    <child link="grinder"/>
    <origin xyz="0 0 0.19798"/>
    <axis xyz="0 0 1"/>
  </joint>
  <link name="grinder">
    <visual>
      <geometry>
        <mesh filename="package://staubli_rx170_support/meshes/visual/grinder.dae"/>
      </geometry>
    </visual>
    <collision>
      <geometry>
        <mesh filename="package://staubli_rx170_support/meshes/collision/grinder.dae"/>
      </geometry>
    </collision>
  </link>
</robot>

